<?xml version="1.0" encoding="utf-8"?>
<!-- This URDF was automatically created by SolidWorks to URDF Exporter! Originally created by Stephen Brawner (brawner@gmail.com) 
     Commit Version: 1.6.0-4-g7f85cfe  Build Version: 1.6.7995.38578
     For more information, please see http://wiki.ros.org/sw_urdf_exporter -->
<robot name="hyumob">
  <material name="black">
    <color rgba="0.0 0.0 0.0 1.0"/>
  </material>
  <material name="blue">
    <color rgba="0.0 0.0 0.8 1.0"/>
  </material>
  <material name="green">
    <color rgba="0.0 0.8 0.0 1.0"/>
  </material>
  <material name="grey_">
    <color rgba="0.2 0.2 0.2 1.0"/>
  </material>
  <material name="orange">
    <color rgba="1.0 0.4235294117647059 0.0392156862745098 1.0"/>
  </material>
  <material name="brown">
    <color rgba="0.8705882352941177 0.8117647058823529 0.7647058823529411 1.0"/>
  </material>
  <material name="red">
    <color rgba="0.8 0.0 0.0 1.0"/>
  </material>
  <material name="white">
    <color rgba="1.0 1.0 1.0 1.0"/>
  </material>
  <material name="metal">
    <color rgba="0.768627450980392 0.749019607843137 0.729411764705882 1"/>
  </material>
  <material name="metal_grey">
    <color rgba="0.501960784313725 0.501960784313725 0.501960784313725 1"/>
  </material>
  <material name="metal_white">
    <color rgba="0.866666666666667 0.866666666666667 0.890196078431373 1"/>
  </material>
  
  <!-- Mobile HYUMob -->
  <link name="world">
      <inertial>
          <mass value="0.000001" />
          <origin xyz="0.0 0.0 0.0" rpy="0 0 0" />
          <inertia ixx="0.000001" ixy="0" ixz="0" iyy="0.000001" iyz="0" izz="0.000001" />
      </inertial>
  </link>
  <joint name="lin_x_joint" type="prismatic">
    <origin rpy="0 0 0" xyz="0 0 0"/>
    <axis xyz="1 0 0"/>
    <limit effort="1000.0" lower="-1e+16" upper="1e+16" velocity="3.5"/>
    <joint_properties damping="1" friction="1"/>
    <parent link="world"/>
    <child link="lin_x_link"/>
  </joint>
  <link name="lin_x_link">
      <inertial>
          <mass value="0.000001" />
          <origin xyz="0.0 0.0 0.0" rpy="0 0 0" />
          <inertia ixx="0.000001" ixy="0" ixz="0" iyy="0.000001" iyz="0" izz="0.000001" />
      </inertial>
  </link>
  <joint name="lin_y_joint" type="prismatic">
    <origin rpy="0 0 0" xyz="0 0 0"/>
    <axis xyz="0 1 0"/>
    <limit effort="1000.0" lower="-1e+16" upper="1e+16" velocity="3.5"/>
    <joint_properties damping="1" friction="1"/>
    <parent link="lin_x_link"/>
    <child link="lin_y_link"/>
  </joint>
  <link name="lin_y_link">
      <inertial>
          <mass value="0.000001" />
          <origin xyz="0.0 0.0 0.0" rpy="0 0 0" />
          <inertia ixx="0.000001" ixy="0" ixz="0" iyy="0.000001" iyz="0" izz="0.000001" />
      </inertial>
  </link>
  <joint name="rot_z_joint" type="revolute">
    <origin rpy="0 0 0" xyz="0 0 0"/>
    <axis xyz="0 0 1"/>
    <limit effort="1000.0" lower="-1e+16" upper="1e+16" velocity="3.5"/>
    <joint_properties damping="1" friction="1"/>
    <parent link="lin_y_link"/>
    <child link="base_link"/>
  </joint>
  <link
    name="base_link">
    <inertial>
      <origin
        xyz="-0.02461277 0 0.15106643"
        rpy="0 0 0" />
      <mass
        value="50.03647319" />
      <inertia
        ixx="2.67652624"
        ixy="0.01131569"
        ixz="-0.083242"
        iyy="5.55238176"
        iyz="6.42E-06"
        izz="5.66864802" />
    </inertial>
    <visual>
      <origin
        xyz="0 0 0"
        rpy="0 0 0" />
      <geometry>
        <mesh
          filename="meshes/stl/base_link.STL" />
      </geometry>
      <material
        name="">
        <color
          rgba="0.79216 0.81961 0.93333 1" />
      </material>
    </visual>
    <collision>
      <origin
        xyz="0 0 0"
        rpy="0 0 0" />
      <geometry>
        <mesh
          filename="meshes/stl/base_link.STL" />
      </geometry>
    </collision>
  </link>
  <link
    name="wheel_left_front">
    <inertial>
      <origin
        xyz="-2.623E-05 0.021795 2.623E-05"
        rpy="0 0 0" />
      <mass
        value="0.8" />
      <inertia
        ixx="0.00044643"
        ixy="-4.1E-07"
        ixz="0"
        iyy="9.628E-05"
        iyz="5E-07"
        izz="0.00044613" />
    </inertial>
    <visual>
      <origin
        xyz="0 0 0"
        rpy="0 0 3.141592" />
      <geometry>
        <mesh
          filename="meshes/stl/wheel_left_front.STL" />
      </geometry>
      <material
        name="">
        <color
          rgba="0.79216 0.81961 0.93333 1" />
      </material>
    </visual>
    <collision>
      <origin
        xyz="0 0 0"
        rpy="0 0 3.141592" />
      <geometry>
        <mesh
          filename="meshes/stl/wheel_left_front.STL" />
      </geometry>
    </collision>
  </link>
  <joint
    name="joint_left_front"
    type="fixed">
    <origin
      xyz="0.41 -0.269 0.08"
      rpy="0 0 0" />
    <parent
      link="base_link" />
    <child
      link="wheel_left_front" />
  </joint>
  <link
    name="wheel_left_back">
    <inertial>
      <origin
        xyz="-2.623E-05 -0.021795 -2.623E-05"
        rpy="0 0 0" />
      <mass
        value="0.8" />
      <inertia
        ixx="0.00044643"
        ixy="-4.1E-07"
        ixz="0"
        iyy="9.628E-05"
        iyz="5E-07"
        izz="0.00044613" />
    </inertial>
    <visual>
      <origin
        xyz="0 0 0"
        rpy="0 0 3.141592" />
      <geometry>
        <mesh
          filename="meshes/stl/wheel_left_back.STL" />
      </geometry>
      <material
        name="">
        <color
          rgba="0.79216 0.81961 0.93333 1" />
      </material>
    </visual>
    <collision>
      <origin
        xyz="0 0 0"
        rpy="0 0 3.141592" />
      <geometry>
        <mesh
          filename="meshes/stl/wheel_left_back.STL" />
      </geometry>
    </collision>
  </link>
  <joint
    name="joint_left_back"
    type="fixed">
    <origin
      xyz="-0.41 -0.269 0.08"
      rpy="0 0 0" />
    <parent
      link="base_link" />
    <child
      link="wheel_left_back" />
  </joint>
  <link
    name="wheel_right_front">
    <inertial>
      <origin
        xyz="-2.623E-05 -0.021795 -2.623E-05"
        rpy="0 0 0" />
      <mass
        value="0.8" />
      <inertia
        ixx="0.00044643"
        ixy="4.1E-07"
        ixz="0"
        iyy="9.628E-05"
        iyz="5E-07"
        izz="0.00044613" />
    </inertial>
    <visual>
      <origin
        xyz="0 0 0"
        rpy="0 0 0" />
      <geometry>
        <mesh
          filename="meshes/stl/wheel_right_front.STL" />
      </geometry>
      <material
        name="">
        <color
          rgba="0.79216 0.81961 0.93333 1" />
      </material>
    </visual>
    <collision>
      <origin
        xyz="0 0 0"
        rpy="0 0 0" />
      <geometry>
        <mesh
          filename="meshes/stl/wheel_right_front.STL" />
      </geometry>
    </collision>
  </link>
  <joint
    name="joint_right_front"
    type="fixed">
    <origin
      xyz="0.41 0.269 0.08"
      rpy="0 0 0" />
    <parent
      link="base_link" />
    <child
      link="wheel_right_front" />
  </joint>
  <link
    name="wheel_right_back">
    <inertial>
      <origin
        xyz="-2.623E-05 -0.021795 -2.623E-05"
        rpy="0 0 0" />
      <mass
        value="0.8" />
      <inertia
        ixx="0.00044643"
        ixy="4.1E-07"
        ixz="0"
        iyy="9.628E-05"
        iyz="5E-07"
        izz="0.00044613" />
    </inertial>
    <visual>
      <origin
        xyz="0 0 0"
        rpy="0 0 0" />
      <geometry>
        <mesh
          filename="meshes/stl/wheel_right_back.STL" />
      </geometry>
      <material
        name="">
        <color
          rgba="0.79216 0.81961 0.93333 1" />
      </material>
    </visual>
    <collision>
      <origin
        xyz="0 0 0"
        rpy="0 0 0" />
      <geometry>
        <mesh
          filename="meshes/stl/wheel_right_back.STL" />
      </geometry>
    </collision>
  </link>
  <joint
    name="joint_right_back"
    type="fixed">
    <origin
      xyz="-0.41 0.269 0.08"
      rpy="0 0 0" />
    <parent
      link="base_link" />
    <child
      link="wheel_right_back" />
  </joint>
  
</robot>
