<?xml version="1.0" encoding="utf-8"?>
<!-- This URDF was automatically created by SolidWorks to URDF Exporter! Originally created by Stephen Brawner (brawner@gmail.com) 
     Commit Version: 1.6.0-4-g7f85cfe  Build Version: 1.6.7995.38578
     For more information, please see http://wiki.ros.org/sw_urdf_exporter -->
<robot name="mobile">
  <!-- Mobile HYUMob -->
  <link name="world">
      <inertial>
          <mass value="0.000001" />
          <origin xyz="0.0 0.0 0.0" rpy="0 0 0" />
          <inertia ixx="0.000001" ixy="0" ixz="0" iyy="0.000001" iyz="0" izz="0.000001" />
      </inertial>
  </link>
  <joint name="lin_x_joint" type="prismatic">
    <origin rpy="0 0 0" xyz="0 0 0"/>
    <axis xyz="1 0 0"/>
    <limit effort="1000.0" lower="-1e+16" upper="1e+16" velocity="3.5"/>
    <joint_properties damping="1" friction="1"/>
    <parent link="world"/>
    <child link="lin_x_link"/>
  </joint>
  <link name="lin_x_link">
      <inertial>
          <mass value="0.000001" />
          <origin xyz="0.0 0.0 0.0" rpy="0 0 0" />
          <inertia ixx="0.000001" ixy="0" ixz="0" iyy="0.000001" iyz="0" izz="0.000001" />
      </inertial>
  </link>
  <joint name="lin_y_joint" type="prismatic">
    <origin rpy="0 0 0" xyz="0 0 0"/>
    <axis xyz="0 1 0"/>
    <limit effort="1000.0" lower="-1e+16" upper="1e+16" velocity="3.5"/>
    <joint_properties damping="1" friction="1"/>
    <parent link="lin_x_link"/>
    <child link="lin_y_link"/>
  </joint>
  <link name="lin_y_link">
      <inertial>
          <mass value="0.000001" />
          <origin xyz="0.0 0.0 0.0" rpy="0 0 0" />
          <inertia ixx="0.000001" ixy="0" ixz="0" iyy="0.000001" iyz="0" izz="0.000001" />
      </inertial>
  </link>
  <joint name="rot_z_joint" type="revolute">
    <origin rpy="0 0 0" xyz="0 0 0"/>
    <axis xyz="0 0 1"/>
    <limit effort="1000.0" lower="-1e+16" upper="1e+16" velocity="3.5"/>
    <joint_properties damping="1" friction="1"/>
    <parent link="lin_y_link"/>
    <child link="base_link"/>
  </joint>
  <link
    name="base_link">
    <inertial>
      <origin
        xyz="0.0 0 0.1"
        rpy="0 0 0" />
      <mass
        value="50.0" />
      <inertia
        ixx="1.70833333"
        ixy="0.0"
        ixz="0.0"
        iyy="3.33333333"
        iyz="0.0"
        izz="3.70833333" />
    </inertial>
    <visual>
      <origin
        xyz="0 0 0"
        rpy="0 0 0" />
      <geometry>
        <mesh
          filename="meshes/stl/base.STL" />
      </geometry>
      <material
        name="">
        <color
          rgba="0.79216 0.81961 0.93333 1" />
      </material>
    </visual>
    <collision>
      <origin
        xyz="0 0 0"
        rpy="0 0 0" />
      <geometry>
        <mesh
          filename="meshes/stl/base.STL" />
      </geometry>
    </collision>
  </link>
  
</robot>
