<?xml version="1.0" ?>
<!-- =================================================================================== -->
<!-- |    This document was autogenerated by xacro from indy7.xacro                    | -->
<!-- |    EDITING THIS FILE BY HAND IS NOT RECOMMENDED                                 | -->
<!-- =================================================================================== -->
<robot name="indy7_dualarm">
  <material name="black">
    <color rgba="0.0 0.0 0.0 1.0"/>
  </material>
  <material name="blue">
    <color rgba="0.0 0.0 0.8 1.0"/>
  </material>
  <material name="green">
    <color rgba="0.0 0.8 0.0 1.0"/>
  </material>
  <material name="grey_">
    <color rgba="0.2 0.2 0.2 1.0"/>
  </material>
  <material name="orange">
    <color rgba="1.0 0.4235294117647059 0.0392156862745098 1.0"/>
  </material>
  <material name="brown">
    <color rgba="0.8705882352941177 0.8117647058823529 0.7647058823529411 1.0"/>
  </material>
  <material name="red">
    <color rgba="0.8 0.0 0.0 1.0"/>
  </material>
  <material name="white">
    <color rgba="1.0 1.0 1.0 1.0"/>
  </material>
  <material name="metal">
    <color rgba="0.768627450980392 0.749019607843137 0.729411764705882 1"/>
  </material>
  <material name="metal_grey">
    <color rgba="0.501960784313725 0.501960784313725 0.501960784313725 1"/>
  </material>
  <material name="metal_white">
    <color rgba="0.866666666666667 0.866666666666667 0.890196078431373 1"/>
  </material>
  <!-- ros_control plugin -->
  <gazebo>
    <plugin filename="libgazebo_ros_control.so" name="gazebo_ros_control"/>
  </gazebo>
  <link name="world">
      <inertial>
          <mass value="0" />
          <origin xyz="0.0 0.0 0.0" rpy="0 0 0" />
          <inertia ixx="0" ixy="0" ixz="0" iyy="0" iyz="0" izz="0" />
      </inertial>
  </link>
  <joint name="world_joint_l" type="fixed">
    <origin rpy="2.094407804564866 0 3.141592" xyz="0 0.1551 1.2924"/>
    <parent link="world"/>
    <child link="link0_l"/>
  </joint>
  <!-- <joint name="world_joint_r" type="fixed">
    <origin rpy="2.094407804564866 0 0" xyz="0 -0.1551 1.2924"/>
    <parent link="world"/>
    <child link="link0_r"/>
  </joint> -->
  
  <!-- <material name="grey"> <color rgba="0.5 0.5 0.5 1"/> </material> -->
  <link name="link0_l">
    <visual>
      <origin rpy="0 0 3.141592" xyz="0 0 0"/>
      <geometry>
        <mesh filename="meshes/stl/Indy7_0.stl"/>
      </geometry>
      <material name="metal_grey"/>
    </visual>

    <inertial>
      <origin xyz="0.00131966 -0.00000218 0.03212832" rpy="0 0 0"/>
      <mass value="1.67030785"/>
      <inertia ixx="+0.00661309" iyy="+0.00644765" izz="+0.00792090" ixy="+0.00000183" iyz="-0.00000027" ixz="+0.00002695"/>
    </inertial>
  </link>
  <link name="link1_l">
    <visual>
      <origin rpy="0 0 0" xyz="0 0 0"/>
      <geometry>
        <mesh filename="meshes/stl/Indy7_1.stl"/>
      </geometry>
      <material name="metal_grey"/>
    </visual>

    <inertial>
      <origin xyz="-0.00023749 -0.04310313 0.13245396" rpy="0 0 0"/>
      <mass value="11.44444535"/>
      <inertia ixx="+0.35065005" iyy="+0.30479800" izz="+0.06003147" ixy="+0.00011931" iyz="-0.10984447" ixz="-0.00037553"/>
    </inertial>
  </link>
  <link name="link2_l">
    <visual>
      <origin rpy="0 0 0" xyz="0 0 0"/>
      <geometry>
        <mesh filename="meshes/stl/Indy7_2.stl"/>
      </geometry>
      <material name="metal_grey"/>
    </visual>

    <inertial>
			<origin xyz="-0.29616699 0.00002254 0.04483069" rpy="0 0 0"/>
			<mass value="5.84766553"/>
			<inertia ixx="+0.03599743" iyy="+0.72293306" izz="+0.70024119" ixy="-0.00004693" iyz="+0.00000176" ixz="-0.05240346"/>
		</inertial>
  </link>
  <link name="link3_l">
    <visual>
      <origin rpy="0 0 0" xyz="0 0 0"/>
      <geometry>
        <mesh filename="meshes/stl/Indy7_3.stl"/>
      </geometry>
      <material name="metal_grey"/>
    </visual>

    <inertial>
			<origin xyz="-0.16804016 0.00021421 -0.07000383" rpy="0 0 0"/>
			<mass value="2.68206064"/>
			<inertia ixx="+0.01617210" iyy="+0.11364055" izz="+0.10022522" ixy="-0.00011817" iyz="-0.00004371" ixz="+0.03341882"/>
		</inertial>
  </link>
  <link name="link4_l">
    <visual>
      <origin rpy="0 0 0" xyz="0 0 0"/>
      <geometry>
        <mesh filename="meshes/stl/Indy7_4.stl"/>
      </geometry>
      <material name="metal_grey"/>
    </visual>

    <inertial>
			<origin xyz="-0.00026847 -0.07098440 0.07649128" rpy="0 0 0"/>
			<mass value="2.12987371"/>
			<inertia ixx="+0.02798891" iyy="+0.01443076" izz="+0.01496211" ixy="+0.00003893" iyz="-0.01266296" ixz="-0.00004768"/>
		</inertial>
  </link>
  <link name="link5_l">
    <visual>
      <origin rpy="0 0 0" xyz="0 0 0"/>
      <geometry>
        <mesh filename="meshes/stl/Indy7_5.stl"/>
      </geometry>
      <material name="metal_grey"/>
    </visual>

    <inertial>
			<origin xyz="-0.09796232 -0.00023114 0.06445892" rpy="0 0 0"/>
			<mass value="2.22412271"/>
			<inertia ixx="+0.01105297" iyy="+0.03698291" izz="+0.02754795" ixy="+0.00005517" iyz="-0.00003740" ixz="-0.01481977"/>
		</inertial>
  </link>
  <link name="link6_l">
    <visual>
      <origin rpy="0 0 0" xyz="0 0 0"/>
      <geometry>
        <mesh filename="meshes/stl/Indy7_6.stl"/>
      </geometry>
      <material name="metal_grey"/>
    </visual>

    <inertial>
			<origin xyz="0.00008147 -0.00046556 0.03079097" rpy="0 0 0"/>
			<mass value="0.38254932"/>
			<inertia ixx="+0.00078982" iyy="+0.00079764" izz="+0.00058319" ixy="-0.00000034" iyz="-0.00000508" ixz="+0.00000083"/>
		</inertial>
  </link>
  <link name="tcp_l">
    <inertial>
      <mass value="0.000001" />
      <origin xyz="0.0 0.0 0.0" rpy="0 0 0" />
      <inertia ixx="0.000001" ixy="0" ixz="0" iyy="0.000001" iyz="0" izz="0.000001" />
    </inertial>
  </link>
<!-- 
  <link name="link0_r">
    <visual>
      <origin rpy="0 0 0" xyz="0 0 0"/>
      <geometry>
        <mesh filename="meshes/stl/Indy7_0.stl"/>
      </geometry>
      <material name="metal_grey"/>
    </visual>

    <inertial>
      <origin xyz="0.00131966 -0.00000218 0.03212832" rpy="0 0 0"/>
      <mass value="1.67030785"/>
      <inertia ixx="+0.00661309" iyy="+0.00644765" izz="+0.00792090" ixy="+0.00000183" iyz="-0.00000027" ixz="+0.00002695"/>
    </inertial>
  </link>
  <link name="link1_r">
    <visual>
      <origin rpy="0 0 0" xyz="0 0 0"/>
      <geometry>
        <mesh filename="meshes/stl/Indy7_1.stl"/>
      </geometry>
      <material name="metal_grey"/>
    </visual>

    <inertial>
      <origin xyz="-0.00023749 -0.04310313 0.13245396" rpy="0 0 0"/>
      <mass value="11.44444535"/>
      <inertia ixx="+0.35065005" iyy="+0.30479800" izz="+0.06003147" ixy="+0.00011931" iyz="-0.10984447" ixz="-0.00037553"/>
    </inertial>
  </link>
  <link name="link2_r">
    <visual>
      <origin rpy="0 0 0" xyz="0 0 0"/>
      <geometry>
        <mesh filename="meshes/stl/Indy7_2.stl"/>
      </geometry>
      <material name="metal_grey"/>
    </visual>

    <inertial>
			<origin xyz="-0.29616699 0.00002254 0.04483069" rpy="0 0 0"/>
			<mass value="5.84766553"/>
			<inertia ixx="+0.03599743" iyy="+0.72293306" izz="+0.70024119" ixy="-0.00004693" iyz="+0.00000176" ixz="-0.05240346"/>
		</inertial>
  </link>
  <link name="link3_r">
    <visual>
      <origin rpy="0 0 0" xyz="0 0 0"/>
      <geometry>
        <mesh filename="meshes/stl/Indy7_3.stl"/>
      </geometry>
      <material name="metal_grey"/>
    </visual>

    <inertial>
			<origin xyz="-0.16804016 0.00021421 -0.07000383" rpy="0 0 0"/>
			<mass value="2.68206064"/>
			<inertia ixx="+0.01617210" iyy="+0.11364055" izz="+0.10022522" ixy="-0.00011817" iyz="-0.00004371" ixz="+0.03341882"/>
		</inertial>
  </link>
  <link name="link4_r">
    <visual>
      <origin rpy="0 0 0" xyz="0 0 0"/>
      <geometry>
        <mesh filename="meshes/stl/Indy7_4.stl"/>
      </geometry>
      <material name="metal_grey"/>
    </visual>

    <inertial>
			<origin xyz="-0.00026847 -0.07098440 0.07649128" rpy="0 0 0"/>
			<mass value="2.12987371"/>
			<inertia ixx="+0.02798891" iyy="+0.01443076" izz="+0.01496211" ixy="+0.00003893" iyz="-0.01266296" ixz="-0.00004768"/>
		</inertial>
  </link>
  <link name="link5_r">
    <visual>
      <origin rpy="0 0 0" xyz="0 0 0"/>
      <geometry>
        <mesh filename="meshes/stl/Indy7_5.stl"/>
      </geometry>
      <material name="metal_grey"/>
    </visual>

    <inertial>
			<origin xyz="-0.09796232 -0.00023114 0.06445892" rpy="0 0 0"/>
			<mass value="2.22412271"/>
			<inertia ixx="+0.01105297" iyy="+0.03698291" izz="+0.02754795" ixy="+0.00005517" iyz="-0.00003740" ixz="-0.01481977"/>
		</inertial>
  </link>
  <link name="link6_r">
    <visual>
      <origin rpy="0 0 0" xyz="0 0 0"/>
      <geometry>
        <mesh filename="meshes/stl/Indy7_6.stl"/>
      </geometry>
      <material name="metal_grey"/>
    </visual>

    <inertial>
			<origin xyz="0.00008147 -0.00046556 0.03079097" rpy="0 0 0"/>
			<mass value="0.38254932"/>
			<inertia ixx="+0.00078982" iyy="+0.00079764" izz="+0.00058319" ixy="-0.00000034" iyz="-0.00000508" ixz="+0.00000083"/>
		</inertial>
  </link>
  <link name="tcp_r">
    <inertial>
      <mass value="0.000001" />
      <origin xyz="0.0 0.0 0.0" rpy="0 0 0" />
      <inertia ixx="0.000001" ixy="0" ixz="0" iyy="0.000001" iyz="0" izz="0.000001" />
    </inertial>
  </link> -->


  <joint name="joint0_l" type="revolute">
    <parent link="link0_l"/>
    <child link="link1_l"/>
    <origin rpy="0 0 0" xyz="0 0 0.0775"/>
    <axis xyz="0 0 1"/>
    <limit effort="10" lower="-3.0543261909900763" upper="3.0543261909900763" velocity="1"/>
  </joint>
  <joint name="joint1_l" type="revolute">
    <parent link="link1_l"/>
    <child link="link2_l"/>
    <origin rpy="1.5707963267948966 1.5707963267948966 0" xyz="0 -0.10900000 0.22200000"/>
    <axis xyz="0 0 1"/>
    <limit effort="10" lower="-3.0543261909900763" upper="3.0543261909900763" velocity="1"/>
  </joint>
  <joint name="joint2_l" type="revolute">
    <parent link="link2_l"/>
    <child link="link3_l"/>
    <origin rpy="0 0 0" xyz="-0.45000000 +0.00000000 -0.03050000"/>
    <axis xyz="0 0 1"/>
    <limit effort="10" lower="-3.0543261909900763" upper="3.0543261909900763" velocity="1"/>
  </joint>
  <joint name="joint3_l" type="revolute">
    <parent link="link3_l"/>
    <child link="link4_l"/>
    <origin rpy="-1.5707963267948966 0 1.5707963267948966" xyz="-0.26700000 +0.00000000 -0.07500000"/>
    <axis xyz="0 0 1"/>
    <limit effort="10" lower="-3.0543261909900763" upper="3.0543261909900763" velocity="1"/>
  </joint>
  <joint name="joint4_l" type="revolute">
    <parent link="link4_l"/>
    <child link="link5_l"/>
    <origin rpy="1.5707963267948966 1.5707963267948966 0" xyz="+0.00000000 -0.11400000 +0.08300000"/>
    <axis xyz="0 0 1"/>
    <limit effort="10" lower="-3.0543261909900763" upper="3.0543261909900763" velocity="1"/>
  </joint>
  <joint name="joint5_l" type="revolute">
    <parent link="link5_l"/>
    <child link="link6_l"/>
    <origin rpy="-1.5707963267948966 0 1.5707963267948966" xyz="-0.16800000 +0.00000000 +0.06900000"/>
    <axis xyz="0 0 1"/>
    <limit effort="10" lower="-3.752457891787808" upper="3.752457891787808" velocity="1"/>
  </joint>
  <joint name="indy7_tcp_l" type="fixed">
    <parent link="link6_l"/>
    <child link="tcp_l"/>
    <origin rpy="0 0 0" xyz="0 0 0.06"/>
  </joint>

  <!-- <joint name="joint0_r" type="revolute">
    <parent link="link0_r"/>
    <child link="link1_r"/>
    <origin rpy="0 0 0" xyz="0 0 0.0775"/>
    <axis xyz="0 0 1"/>
    <limit effort="10" lower="-3.0543261909900763" upper="3.0543261909900763" velocity="1"/>
  </joint>
  <joint name="joint1_r" type="revolute">
    <parent link="link1_r"/>
    <child link="link2_r"/>
    <origin rpy="1.5707963267948966 1.5707963267948966 0" xyz="0 -0.10900000 0.22200000"/>
    <axis xyz="0 0 1"/>
    <limit effort="10" lower="-3.0543261909900763" upper="3.0543261909900763" velocity="1"/>
  </joint>
  <joint name="joint2_r" type="revolute">
    <parent link="link2_r"/>
    <child link="link3_r"/>
    <origin rpy="0 0 0" xyz="-0.45000000 +0.00000000 -0.03050000"/>
    <axis xyz="0 0 1"/>
    <limit effort="10" lower="-3.0543261909900763" upper="3.0543261909900763" velocity="1"/>
  </joint>
  <joint name="joint3_r" type="revolute">
    <parent link="link3_r"/>
    <child link="link4_r"/>
    <origin rpy="-1.5707963267948966 0 1.5707963267948966" xyz="-0.26700000 +0.00000000 -0.07500000"/>
    <axis xyz="0 0 1"/>
    <limit effort="10" lower="-3.0543261909900763" upper="3.0543261909900763" velocity="1"/>
  </joint>
  <joint name="joint4_r" type="revolute">
    <parent link="link4_r"/>
    <child link="link5_r"/>
    <origin rpy="1.5707963267948966 1.5707963267948966 0" xyz="+0.00000000 -0.11400000 +0.08300000"/>
    <axis xyz="0 0 1"/>
    <limit effort="10" lower="-3.0543261909900763" upper="3.0543261909900763" velocity="1"/>
  </joint>
  <joint name="joint5_r" type="revolute">
    <parent link="link5_r"/>
    <child link="link6_r"/>
    <origin rpy="-1.5707963267948966 0 1.5707963267948966" xyz="-0.16800000 +0.00000000 +0.06900000"/>
    <axis xyz="0 0 1"/>
    <limit effort="10" lower="-3.752457891787808" upper="3.752457891787808" velocity="1"/>
  </joint>
  <joint name="indy7_tcp_r" type="fixed">
    <parent link="link6_r"/>
    <child link="tcp_r"/>
    <origin rpy="0 0 0" xyz="0 0 0.06"/>
  </joint> -->
</robot>

