<?xml version="1.0" encoding="utf-8"?>
<!-- This URDF was automatically created by SolidWorks to URDF Exporter! Originally created by Stephen Brawner (brawner@gmail.com) 
 Commit Version: 1.6.0-4-g7f85cfe  Build Version: 1.6.7995.38578
 For more information, please see http://wiki.ros.org/sw_urdf_exporter -->
<robot
  name="KARM_EQM">
  <link
    name="world">
  </link>

  <joint
    name="world_fixed" type="fixed">
    <origin
      xyz="0 0 0"
      rpy="0 0 0" />
    <parent
      link="world" />
    <child
      link="link0" />
  </joint>

  <link
    name="link0">
    <inertial>
    <origin  xyz="-1.94614e-05 2.10811e-06 0.0907434" rpy="0 0 0" />
    <mass
      value="4.48218" />    
    <inertia
      ixx="0.04755097476"
      ixy="0"
      ixz="0"
      iyy="0.04755157166"
      iyz="0"
      izz="0.009810637759999999" />
      </inertial>
      <visual>
    <origin
      xyz="0 0 0"
      rpy="0 0 0" />
    <geometry>
      <mesh
    filename="meshes/link0.stl" />
    </geometry>
    <material
      name="">
      <color
    rgba="0.75294 0.75294 0.75294 1" />
    </material>
      </visual>
      <collision>
    <origin
      xyz="0 0 0"
      rpy="0 0 0" />
    <geometry>
      <mesh
    filename="meshes/link0.stl" />
    </geometry>
      </collision>
  </link>

  <link
    name="link1">
    <inertial>
  <origin
    xyz="2.3384E-07 -0.092223 0.11738"
    rpy="0 0 0" />
  <mass
    value="4.4336" />
  <inertia
    ixx="0.01957"
    ixy="-8.1642E-08"
    ixz="-1.6766E-07"
    iyy="0.01425"
    iyz="-1.2661E-07"
    izz="0.018753" />
    </inertial>
    <visual>
  <origin
    xyz="0 0 0"
    rpy="0 0 0" />
  <geometry>
    <mesh
  filename="meshes/link1.stl" />
  </geometry>
  <material
    name="">
    <color
  rgba="0.75294 0.75294 0.75294 1" />
  </material>
    </visual>
    <collision>
  <origin
    xyz="0 0 0"
    rpy="0 0 0" />
  <geometry>
    <mesh
  filename="meshes/link1.stl" />
  </geometry>
    </collision>
  </link>

  <joint
    name="joint1"
    type="revolute">
    <origin
  xyz="0 0 0.128"
  rpy="0 0 0" />
    <parent
  link="link0" />
    <child
  link="link1" />
    <axis
  xyz="0 0 1" />
    <limit
  lower="-3.14"
  upper="3.14"
  effort="100"
  velocity="10" />
  </joint>

  <link
    name="link2">
    <inertial>
  <origin
    xyz="-3.93948776822306E-07 0.0838973300188179 0.445211092670025"
    rpy="0 0 0" />
  <mass
    value="5.33597958831089" />
  <inertia
    ixx="0.213961008059972"
    ixy="-8.8991531588552E-08"
    ixz="1.77351738759195E-07"
    iyy="0.214494867107806"
    iyz="0.000230411032949535"
    izz="0.0176405999483848" />
    </inertial>
    <visual>
  <origin
    xyz="0 0 0"
    rpy="0 0 0" />
  <geometry>
    <mesh
  filename="meshes/link2.stl" />
  </geometry>
  <material
    name="">
    <color
  rgba="0.752941176470588 0.752941176470588 0.752941176470588 1" />
  </material>
    </visual>
    <collision>
  <origin
    xyz="0 0 0"
    rpy="0 0 0" />
  <geometry>
    <mesh
  filename="meshes/link2.stl" />
  </geometry>
    </collision>
  </link>
  <joint
    name="joint2"
    type="revolute">
    <origin
  xyz="0 0.0915 0.128"
  rpy="0 0 0" />
    <parent
  link="link1" />
    <child
  link="link2" />
    <axis
  xyz="0 1 0" />
    <limit
  lower="-3.14"
  upper="3.14"
  effort="100"
  velocity="10" />
  </joint>
  <link
    name="link3">
    <inertial>
  <origin
    xyz="-0.0055167 -0.0064991 0.25231"
    rpy="0 0 0" />
  <mass
    value="4.3966" />
  <inertia
    ixx="0.018267"
    ixy="5.1261E-06"
    ixz="-0.00012787"
    iyy="0.019019"
    iyz="-0.00023035"
    izz="0.012414" />
    </inertial>
    <visual>
  <origin
    xyz="0 0 0"
    rpy="0 0 0" />
  <geometry>
    <mesh
  filename="meshes/link3.stl" />
  </geometry>
  <material
    name="">
    <color
  rgba="0.75294 0.75294 0.75294 1" />
  </material>
    </visual>
    <collision>
  <origin
    xyz="0 0 0"
    rpy="0 0 0" />
  <geometry>
    <mesh
  filename="meshes/link3.stl" />
  </geometry>
    </collision>
  </link>
  <joint
    name="joint3"
    type="revolute">
    <origin
  xyz="0 0.0915 1.0012"
  rpy="0 0.021863 0" />
    <parent
  link="link2" />
    <child
  link="link3" />
    <axis
  xyz="0 0 1" />
    <limit
  lower="-3.14"
  upper="3.14"
  effort="100"
  velocity="10" />
  </joint>
  <link
    name="link4">
    <inertial>
  <origin
    xyz="5.43014370024686E-07 -0.0815218003075672 0.255564565651163"
    rpy="0 0 0" />
  <mass
    value="4.06563238726737" />
  <inertia
    ixx="0.0454368543057323"
    ixy="-8.89915317752555E-08"
    ixz="-1.77351738474063E-07"
    iyy="0.0459728262673695"
    iyz="-0.00023041103295395"
    izz="0.0126687782287841" />
    </inertial>
    <visual>
  <origin
    xyz="0 0 0"
    rpy="0 0 0" />
  <geometry>
    <mesh
  filename="meshes/link4.stl" />
  </geometry>
  <material
    name="">
    <color
  rgba="0.752941176470588 0.752941176470588 0.752941176470588 1" />
  </material>
    </visual>
    <collision>
  <origin
    xyz="0 0 0"
    rpy="0 0 0" />
  <geometry>
    <mesh
  filename="meshes/link4.stl" />
  </geometry>
    </collision>
  </link>
  <joint
    name="joint4"
    type="revolute">
    <origin
  xyz="-0.009811 -0.0915 0.44867"
  rpy="0 -0.021863 0" />
    <parent
  link="link3" />
    <child
  link="link4" />
    <axis
  xyz="0 1 0" />
    <limit
  lower="-3.14"
  upper="3.14"
  effort="100"
  velocity="10" />
  </joint>
  <link
    name="link5">
    <inertial>
  <origin
    xyz="4.96056726029259E-07 -0.00649913721947383 0.249091685649315"
    rpy="0 0 0" />
  <mass
    value="4.39661533299087" />
  <inertia
    ixx="0.0182694722630793"
    ixy="8.89915318157946E-08"
    ixz="1.77351737975263E-07"
    iyy="0.0190193636143894"
    iyz="-0.000230411032953463"
    izz="0.0124110841865249" />
    </inertial>
    <visual>
  <origin
    xyz="0 0 0"
    rpy="0 0 0" />
  <geometry>
    <mesh
  filename="meshes/link5.stl" />
  </geometry>
  <material
    name="">
    <color
  rgba="0.752941176470588 0.752941176470588 0.752941176470588 1" />
  </material>
    </visual>
    <collision>
  <origin
    xyz="0 0 0"
    rpy="0 0 0" />
  <geometry>
    <mesh
  filename="meshes/link5.stl" />
  </geometry>
    </collision>
  </link>
  <joint
    name="joint5"
    type="revolute">
    <origin
  xyz="0 -0.0915 0.6045"
  rpy="0 0 0" />
    <parent
  link="link4" />
    <child
  link="link5" />
    <axis
  xyz="0 0 1" />
    <limit
  lower="-3.14"
  upper="3.14"
  effort="100"
  velocity="10" />
  </joint>
  <link
    name="link6">
    <inertial>
  <origin
    xyz="-2.23972017487917E-07 -0.0861596456675721 -0.0809142046865783"
    rpy="0 0 0" />
  <mass
    value="4.62888290048359" />
  <inertia
    ixx="0.0198168881314805"
    ixy="8.16421812785018E-08"
    ixz="-1.67655476143055E-07"
    iyy="0.0206880568575693"
    iyz="1.26613274288579E-07"
    izz="0.0131983162246771" />
    </inertial>
    <visual>
  <origin
    xyz="0 0 0"
    rpy="0 0 0" />
  <geometry>
    <mesh
  filename="meshes/link6.stl" />
  </geometry>
  <material
    name="">
    <color
  rgba="0.752941176470588 0.752941176470588 0.752941176470588 1" />
  </material>
    </visual>
    <collision>
  <origin
    xyz="0 0 0"
    rpy="0 0 0" />
  <geometry>
    <mesh
  filename="meshes/link6.stl" />
  </geometry>
    </collision>
  </link>
  <joint
    name="joint6"
    type="revolute">
    <origin
  xyz="0 -0.0915 0.4455"
  rpy="0 0 0" />
    <parent
  link="link5" />
    <child
  link="link6" />
    <axis
  xyz="0 1 0" />
    <limit
  lower="-3.14"
  upper="3.14"
  effort="100"
  velocity="10" />
  </joint>
  <link
    name="link7">
    <inertial>
  <origin
    xyz="6.6613E-16 7.111E-14 0.043063"
    rpy="0 0 0" />
  <mass
    value="1.2654" />
  <inertia
    ixx="0.0017722"
    ixy="2.6971E-19"
    ixz="-3.0047E-19"
    iyy="0.0017722"
    iyz="1.4611E-19"
    izz="0.002693" />
    </inertial>
    <visual>
  <origin
    xyz="0 0 0"
    rpy="0 0 0" />
  <geometry>
    <mesh
  filename="meshes/link7.stl" />
  </geometry>
  <material
    name="">
    <color
  rgba="0.75294 0.75294 0.75294 1" />
  </material>
    </visual>
    <collision>
  <origin
    xyz="0 0 0"
    rpy="0 0 0" />
  <geometry>
    <mesh
  filename="meshes/link7.stl" />
  </geometry>
    </collision>
  </link>
  <joint
    name="joint7"
    type="revolute">
    <origin
  xyz="0 -0.0915 0.128"
  rpy="0 0 0" />
    <parent
  link="link6" />
    <child
  link="link7" />
    <axis
  xyz="0 0 1" />
    <limit
  lower="-3.14"
  upper="3.14"
  effort="100"
  velocity="10" />
  </joint>

    <joint
    name="eef_fixed"
    type="fixed">
    <origin
      xyz="0 0 0.087"
      rpy="0 0 0" />
    <parent
      link="link7" />
    <child
      link="eef_link" />
  </joint>    
  
  <link  name="eef_link">
  <inertial>
    <origin
      xyz="0 0 0"
      rpy="0 0 0" />
    <mass
      value="0.0" />
    <inertia
      ixx="0.000000000001"
      ixy="0.0"
      ixz="0.0"
      iyy="0.000000000001"
      iyz="0.0"
      izz="0.000000000001" />
  </inertial>
  <visual>
    <origin
      xyz="0 0 0"
      rpy="0 0 0" />
    <geometry>
      <box size="0.01 0.01 0.01"/>
    </geometry>
    <material
      name="red">
      <color
        rgba="1.0 0 0 1" />
    </material>
  </visual>    
</link>
</robot>
